<robot name="RobotArm_latest_v4">
	<link name="base_link"/>
	<link name="link1"/>
	<link name="link2"/>
	<link name="link3"/>
	<link name="link4"/>
	<link name="link5"/>
	<link name="link6"/>
	<link name="link7"/>

	<joint name="rev0" type="continuous">
		<parent link="base_link"/>
		<child link="link1"/>
		<origin rpy="0 0 0" xyz="0 0 0.048"/>
		<axis xyz="0 0 -1.0"/>
	</joint>
	<joint name="rev1" type="continuous">
		<parent link="link1"/>
		<child link="link2"/>
		<origin rpy="0 0 0" xyz="-0.0 0 0.1"/>
		<axis xyz="-1.0 0 0"/>
	</joint>
	<joint name="rev2" type="continuous">
		<parent link="link2"/>
		<child link="link3"/>
		<!-- <origin rpy="0 0 0" xyz="0.04550000000005672 0.030999999999995993 0.29650000000128046"/> -->
		<origin rpy="0 0 0" xyz="0 0 0.29650000000128046"/>
		<axis xyz="1.0 0 0"/>
	</joint>
	<joint name="rev3" type="continuous">
		<parent link="link3"/>
		<child link="link4"/>
		<origin rpy="0 0 0" xyz="0 -0.0 0.30"/>
		<axis xyz="1.0 0 0"/>
	</joint>
	<joint name="rev4" type="continuous">
		<parent link="link4"/>
		<child link="link5"/>
		<origin rpy="0 0 0" xyz="0 0 0.06149999999619804"/>
		<axis xyz="0 0 -1"/>
	</joint>
	<!-- <joint name="rev5" type="continuous"> 
		<parent link="link5"/>
		<child link="link6"/>
		<origin rpy="0 0 0" xyz="0 0 0.11499999999999366"/>
		<axis xyz="0 1 0"/>
	</joint>
	<joint name="rev6" type="continuous">
		<parent link="link6"/>
		<child link="link7"/>
		<origin rpy="0 0 0" xyz="0 0 0.0694999999961976"/>
		<axis xyz="0 0 -1"/>
	</joint> -->
</robot>

